Workbook
Name A180000000: #REF!
Name A1999999: #REF!
Name A9999999: #REF!
Name A99999999: #REF!
Name A999999999: #REF!
Name A999999999999999: #REF!

Sheet Chantier
A1: 03607A39 | B1: CTA
A2: 03607A42 | B2: P41
A3: 22910A01 | B3: P47
A4: 24975A01 | B4: PLO
A5: 20834A02 | B5: SCII
A6: 22923A01 | B6: BW
A7: 12397A01 | B7: GS CA

Sheet Mars
C1: Date:
C2: 46023 | D2: =TODAY() -> 46119 | E2: =NOW() -> 46119.643
E4: Matin | I4: Après midi | M4: Total
D5: Jour | E5: hh | F5: mm | G5: hh | H5: mm | I5: hh | J5: mm | K5: hh | L5: mm | M5: Matin | N5: Après midi | O5: journée | P5: Du | Q5: Sup. | R5: Chantiers | X5: Remarques
C6: =C2 -> 46023 | D6: lundi | M6: =((G6+H6/60)-(E6+F6/60)) -> 0 | N6: =((K6+L6/60)-(I6+J6/60)) -> 0 | O6: =N6+M6 -> 0 | P6: 8.5 | Q6: =ROUND(IF(O6>0,(O6-P6)+Q2,+Q2),2) -> 0
C7: =C6+1 -> 46024 | D7: mardi | M7: =((G7+H7/60)-(E7+F7/60)) -> 0 | N7: =((K7+L7/60)-(I7+J7/60)) -> 0 | O7: =N7+M7 -> 0 | P7: 8.5 | Q7: =ROUND(IF(O7>0,(O7-P7)+Q6,+Q6),2) -> 0
C8: =C7+1 -> 46025 | D8: mercredi | M8: =((G8+H8/60)-(E8+F8/60)) -> 0 | N8: =((K8+L8/60)-(I8+J8/60)) -> 0 | O8: =N8+M8 -> 0 | P8: 8.5 | Q8: =ROUND(IF(O8>0,(O8-P8)+Q7,+Q7),2) -> 0
C9: =C8+1 -> 46026 | D9: jeudi | M9: =((G9+H9/60)-(E9+F9/60)) -> 0 | N9: =((K9+L9/60)-(I9+J9/60)) -> 0 | O9: =N9+M9 -> 0 | P9: 8.5 | Q9: =ROUND(IF(O9>0,(O9-P9)+Q8,+Q8),2) -> 0
C10: =C9+1 -> 46027 | D10: vendredi | M10: =((G10+H10/60)-(E10+F10/60)) -> 0 | N10: =((K10+L10/60)-(I10+J10/60)) -> 0 | O10: =N10+M10 -> 0 | P10: 8 | Q10: =ROUND(IF(O10>0,(O10-P10)+Q9,+Q9),2) -> 0
C11: =C10+1 -> 46028 | D11: samedi | M11: =((G11+H11/60)-(E11+F11/60)) -> 0 | N11: =((K11+L11/60)-(I11+J11/60)) -> 0 | O11: =N11+M11 -> 0 | Q11: =ROUND(IF(O11>0,(O11-P11)+Q10,+Q10),2) -> 0
C12: =C11+1 -> 46029 | D12: dimanche | M12: =((G12+H12/60)-(E12+F12/60)) -> 0 | N12: =((K12+L12/60)-(I12+J12/60)) -> 0 | O12: =N12+M12 -> 0 | Q12: =ROUND(IF(O12>0,(O12-P12)+Q11,+Q11),2) -> 0
C13: =C12+1 -> 46030 | D13: lundi | M13: =((G13+H13/60)-(E13+F13/60)) -> 0 | N13: =((K13+L13/60)-(I13+J13/60)) -> 0 | O13: =N13+M13 -> 0 | P13: 8.5 | Q13: =ROUND(IF(O13>0,(O13-P13)+Q12,+Q12),2) -> 0
C14: =C13+1 -> 46031 | D14: mardi | M14: =((G14+H14/60)-(E14+F14/60)) -> 0 | N14: =((K14+L14/60)-(I14+J14/60)) -> 0 | O14: =N14+M14 -> 0 | P14: 8.5 | Q14: =ROUND(IF(O14>0,(O14-P14)+Q13,+Q13),2) -> 0
C15: =C14+1 -> 46032 | D15: mercredi | M15: =((G15+H15/60)-(E15+F15/60)) -> 0 | N15: =((K15+L15/60)-(I15+J15/60)) -> 0 | O15: =N15+M15 -> 0 | P15: 8.5 | Q15: =ROUND(IF(O15>0,(O15-P15)+Q14,+Q14),2) -> 0
C16: =C15+1 -> 46033 | D16: jeudi | M16: =((G16+H16/60)-(E16+F16/60)) -> 0 | N16: =((K16+L16/60)-(I16+J16/60)) -> 0 | O16: =N16+M16 -> 0 | P16: 8.5 | Q16: =ROUND(IF(O16>0,(O16-P16)+Q15,+Q15),2) -> 0
C17: =C16+1 -> 46034 | D17: vendredi | M17: =((G17+H17/60)-(E17+F17/60)) -> 0 | N17: =((K17+L17/60)-(I17+J17/60)) -> 0 | O17: =N17+M17 -> 0 | P17: 8 | Q17: =ROUND(IF(O17>0,(O17-P17)+Q16,+Q16),2) -> 0
C18: =C17+1 -> 46035 | D18: samedi | M18: =((G18+H18/60)-(E18+F18/60)) -> 0 | N18: =((K18+L18/60)-(I18+J18/60)) -> 0 | O18: =N18+M18 -> 0 | Q18: =ROUND(IF(O18>0,(O18-P18)+Q17,+Q17),2) -> 0
C19: =C18+1 -> 46036 | D19: dimanche | M19: =((G19+H19/60)-(E19+F19/60)) -> 0 | N19: =((K19+L19/60)-(I19+J19/60)) -> 0 | O19: =N19+M19 -> 0 | Q19: =ROUND(IF(O19>0,(O19-P19)+Q18,+Q18),2) -> 0
C20: =C19+1 -> 46037 | D20: lundi | M20: =((G20+H20/60)-(E20+F20/60)) -> 0 | N20: =((K20+L20/60)-(I20+J20/60)) -> 0 | O20: =N20+M20 -> 0 | P20: 8.5 | Q20: =ROUND(IF(O20>0,(O20-P20)+Q19,+Q19),2) -> 0
C21: =C20+1 -> 46038 | D21: mardi | M21: =((G21+H21/60)-(E21+F21/60)) -> 0 | N21: =((K21+L21/60)-(I21+J21/60)) -> 0 | O21: =N21+M21 -> 0 | P21: 8.5 | Q21: =ROUND(IF(O21>0,(O21-P21)+Q20,+Q20),2) -> 0
C22: =C21+1 -> 46039 | D22: mercredi | M22: =((G22+H22/60)-(E22+F22/60)) -> 0 | N22: =((K22+L22/60)-(I22+J22/60)) -> 0 | O22: =N22+M22 -> 0 | P22: 8.5 | Q22: =ROUND(IF(O22>0,(O22-P22)+Q21,+Q21),2) -> 0
C23: =C22+1 -> 46040 | D23: jeudi | M23: =((G23+H23/60)-(E23+F23/60)) -> 0 | N23: =((K23+L23/60)-(I23+J23/60)) -> 0 | O23: =N23+M23 -> 0 | P23: 8.5 | Q23: =ROUND(IF(O23>0,(O23-P23)+Q22,+Q22),2) -> 0
C24: =C23+1 -> 46041 | D24: vendredi | M24: =((G24+H24/60)-(E24+F24/60)) -> 0 | N24: =((K24+L24/60)-(I24+J24/60)) -> 0 | O24: =N24+M24 -> 0 | P24: 8 | Q24: =ROUND(IF(O24>0,(O24-P24)+Q23,+Q23),2) -> 0
C25: =C24+1 -> 46042 | D25: samedi | M25: =((G25+H25/60)-(E25+F25/60)) -> 0 | N25: =((K25+L25/60)-(I25+J25/60)) -> 0 | O25: =N25+M25 -> 0 | Q25: =ROUND(IF(O25>0,(O25-P25)+Q24,+Q24),2) -> 0
C26: =C25+1 -> 46043 | D26: dimanche | M26: =((G26+H26/60)-(E26+F26/60)) -> 0 | N26: =((K26+L26/60)-(I26+J26/60)) -> 0 | O26: =N26+M26 -> 0 | Q26: =ROUND(IF(O26>0,(O26-P26)+Q25,+Q25),2) -> 0
C27: =C26+1 -> 46044 | D27: lundi | M27: =((G27+H27/60)-(E27+F27/60)) -> 0 | N27: =((K27+L27/60)-(I27+J27/60)) -> 0 | O27: =N27+M27 -> 0 | P27: 8.5 | Q27: =ROUND(IF(O27>0,(O27-P27)+Q26,+Q26),2) -> 0
C28: =C27+1 -> 46045 | D28: mardi | M28: =((G28+H28/60)-(E28+F28/60)) -> 0 | N28: =((K28+L28/60)-(I28+J28/60)) -> 0 | O28: =N28+M28 -> 0 | P28: 8.5 | Q28: =ROUND(IF(O28>0,(O28-P28)+Q27,+Q27),2) -> 0
C29: =C28+1 -> 46046 | D29: mercredi | M29: =((G29+H29/60)-(E29+F29/60)) -> 0 | N29: =((K29+L29/60)-(I29+J29/60)) -> 0 | O29: =N29+M29 -> 0 | P29: 8.5 | Q29: =ROUND(IF(O29>0,(O29-P29)+Q28,+Q28),2) -> 0
C30: =C29+1 -> 46047 | D30: jeudi | M30: =((G30+H30/60)-(E30+F30/60)) -> 0 | N30: =((K30+L30/60)-(I30+J30/60)) -> 0 | O30: =N30+M30 -> 0 | P30: 8.5 | Q30: =ROUND(IF(O30>0,(O30-P30)+Q29,+Q29),2) -> 0
C31: =C30+1 -> 46048 | D31: vendredi | M31: =((G31+H31/60)-(E31+F31/60)) -> 0 | N31: =((K31+L31/60)-(I31+J31/60)) -> 0 | O31: =N31+M31 -> 0 | P31: 8 | Q31: =ROUND(IF(O31>0,(O31-P31)+Q30,+Q30),2) -> 0
C32: =C31+1 -> 46049 | D32: samedi | M32: =((G32+H32/60)-(E32+F32/60)) -> 0 | N32: =((K32+L32/60)-(I32+J32/60)) -> 0 | O32: =N32+M32 -> 0 | Q32: =ROUND(IF(O32>0,(O32-P32)+Q31,+Q31),2) -> 0
C33: =C32+1 -> 46050 | D33: dimanche | M33: =((G33+H33/60)-(E33+F33/60)) -> 0 | N33: =((K33+L33/60)-(I33+J33/60)) -> 0 | O33: =N33+M33 -> 0 | Q33: =ROUND(IF(O33>0,(O33-P33)+Q32,+Q32),2) -> 0
C34: =C33+1 -> 46051 | D34: lundi | M34: =((G34+H34/60)-(E34+F34/60)) -> 0 | N34: =((K34+L34/60)-(I34+J34/60)) -> 0 | O34: =N34+M34 -> 0 | P34: 8.5 | Q34: =ROUND(IF(O34>0,(O34-P34)+Q33,+Q33),2) -> 0
C35: =C34+1 -> 46052 | D35: mardi | M35: =((G35+H35/60)-(E35+F35/60)) -> 0 | N35: =((K35+L35/60)-(I35+J35/60)) -> 0 | O35: =N35+M35 -> 0 | P35: 8.5 | Q35: =ROUND(IF(O35>0,(O35-P35)+Q34,+Q34),2) -> 0
C36: =C35+1 -> 46053 | D36: mercredi | M36: =((G36+H36/60)-(E36+F36/60)) -> 0 | N36: =((K36+L36/60)-(I36+J36/60)) -> 0 | O36: =N36+M36 -> 0 | P36: 8.5 | Q36: =ROUND(IF(O36>0,(O36-P36)+Q35,+Q35),2) -> 0
C37: =C36+1 -> 46054 | D37: jeudi | M37: =((G37+H37/60)-(E37+F37/60)) -> 0 | N37: =((K37+L37/60)-(I37+J37/60)) -> 0 | O37: =N37+M37 -> 0 | P37: 8.5 | Q37: =ROUND(IF(O37>0,(O37-P37)+Q36,+Q36),2) -> 0
C38: =C37+1 -> 46055 | D38: vendredi | M38: =((G38+H38/60)-(E38+F38/60)) -> 0 | N38: =((K38+L38/60)-(I38+J38/60)) -> 0 | O38: =N38+M38 -> 0 | P38: 8 | Q38: =ROUND(IF(O38>0,(O38-P38)+Q37,+Q37),2) -> 0
O39: =SUM(O6:O38) -> 0 | R39: {=SUM(S6:S38+U6:U38+W6:W38)} -> 0
C40: N° Chantier | D40: Chantier
C41: =INDEX(Chantier!A:A,MATCH(D41,Chantier!B:B,0)) -> #N/A | E41: =SUMIF(R5:R37,D41&"*",S5:S37)+SUMIF(T5:T37,D41&"*",U5:U37)+SUMIF(V5:V37,D41&"*",W5:W37) -> 0
...
